Workbook

Sheet Overview
A1: San Diego Gulls — Forensic Model Workbook
A2: Historical base: FY2021-22 to FY2025-26 public anchors + modeled estimates | Baseline projection: FY2026-27
A4: 2025-26 Avg Attendance | C4: 2025-26 Gross Revenue | E4: 2026-27 Gross Revenue | G4: 2026-27 EBITDA | I4: 2026-27 Valuation
A5: =Master_Model!I3 -> 7403 | C5: =Master_Model!I49 -> 11210427 | E5: =Master_Model!J49 -> 12031865 | G5: =Master_Model!J95 -> 1682309 | I5: =Master_Model!J99 -> 38501968
A8: What this workbook does • Converts publicly available Gulls data into a clean operating model. • Separates public facts from logical estimates and projections. • Gives an upside framework for attendance, ticket yield, ancillary spend and sponsorship. Modeling discipline • Public items are linked to the Assumptions and Source_Log tabs. • Private economics (EBITDA, parking share, sponsorship mix, parent subsidy) are clearly labeled as modeled estimates. | G8: High-level readout • Attendance recovered from 6,992 in 2021-22 to 7,403 in 2025-26. • STM entry price rose from $476 to $614 over the same span. • Promotional intensity expanded from 13 theme nights to 28 announced nights. • The 2026-27 upside cases show how operational discipline can push revenue, EBITDA and implied franchise value higher.

Sheet Assumptions
A1: San Diego Gulls — Assumptions & Public Inputs
A2: Blue-font cells are hardcoded historical inputs / modeled estimates. Black-font cells in 2026-27 are formula-driven projections where applicable.
A4: Category | B4: Driver | C4: 2021-22 | D4: 2022-23 | E4: 2023-24 | F4: 2024-25 | G4: 2025-26 | H4: 2026-27 | I4: Unit | J4: Source / Method | K4: Status
A5: CONTROL | B5: 2026-27 attendance growth assumption | H5: 0.03 | I5: pct | J5: Model control | K5: Control
A6: CONTROL | B6: 2026-27 WATP growth assumption | H6: 0.032 | I6: pct | J6: Model control | K6: Control
A7: CONTROL | B7: 2026-27 sponsorship growth assumption | H7: 0.093 | I7: pct | J7: Model control | K7: Control
A8: CONTROL | B8: 2026-27 per-cap F&B growth assumption | H8: 0.032 | I8: pct | J8: Model control | K8: Control
A9: CONTROL | B9: 2026-27 merch per-cap growth assumption | H9: 0.044 | I9: pct | J9: Model control | K9: Control
A10: CONTROL | B10: 2026-27 STM price growth assumption | H10: 0.03 | I10: pct | J10: Model control | K10: Control
A11: CONTROL | B11: 2026-27 single-game price growth assumption | H11: 0.043 | I11: pct | J11: Model control | K11: Control
A12: CONTROL | B12: 2026-27 website traffic growth assumption | H12: 0.08 | I12: pct | J12: Model control | K12: Control
A13: ATTENDANCE | B13: Average attendance | C13: 6992 | D13: 6953 | E13: 7249 | F13: 7262 | G13: 7403 | H13: =ROUND(G13*(1+$H$5),0) -> 7625 | I13: fans/game | J13: https://www.hockeydb.com/stte/san-diego-gulls-11619.html | K13: Public/Projection
A14: ATTENDANCE | B14: Home games | C14: 34 | D14: 36 | E14: 36 | F14: 36 | G14: 36 | H14: 36 | I14: games | J14: https://www.sandiegogulls.com/news/detail/san-diego-gulls-2021-22-schedule-announced | K14: Public
A15: VENUE | B15: Hockey seating capacity | C15: 12920 | D15: 12920 | E15: 12920 | F15: 12920 | G15: 12920 | H15: 12920 | I15: seats | J15: https://www.sandiegogulls.com/assets/doc/2021-22-San-Diego-Gulls-Media-Guide-compressed-92470e4558.pdf | K15: Context
A16: VENUE | B16: General venue capacity | C16: 14000 | D16: 14000 | E16: 14000 | F16: 14000 | G16: 14000 | H16: 14000 | I16: seats | J16: https://pechangaarenasd.com/about/ | K16: Public
A17: SCHEDULE | B17: Home weekend dates | C17: 23 | D17: 23 | E17: 26 | F17: 25 | G17: 25 | H17: 25 | I17: dates | J17: Multiple official schedule releases on sandiegogulls.com | K17: Public
A18: SCHEDULE | B18: Friday home games | C18: 11 | D18: 12 | E18: 12 | F18: 9 | G18: 10 | H18: 10 | I18: games | J18: Multiple official schedule releases on sandiegogulls.com | K18: Public
A19: SCHEDULE | B19: Saturday home games | C19: 11 | D19: 11 | E19: 12 | F19: 14 | G19: 10 | H19: 11 | I19: games | J19: Multiple official schedule releases on sandiegogulls.com | K19: Public/Projection
A20: SCHEDULE | B20: Sunday home games | C20: 1 | D20: 1 | E20: 2 | F20: 2 | G20: 5 | H20: 4 | I20: games | J20: Multiple official schedule releases on sandiegogulls.com | K20: Public/Projection
A21: SCHEDULE | B21: Back-to-back sets | C21: 24 | D21: 21 | E21: 18 | F21: 20 | G21: 22 | H21: 22 | I21: sets | J21: Multiple official schedule releases on sandiegogulls.com | K21: Public
A22: MARKETING | B22: Promotional/theme nights announced | C22: 13 | D22: 15 | E22: 16 | F22: 23 | G22: 28 | H22: 30 | I22: nights | J22: Multiple official promo releases on sandiegogulls.com | K22: Public/Projection
A23: MARKETING | B23: Giveaway items announced | C23: 7 | D23: 6 | E23: 10 | F23: 11 | G23: 5 | H23: 6 | I23: items | J23: Multiple official promo releases on sandiegogulls.com | K23: Public/Projection
A24: MARKETING | B24: Pregame tailgates | C24: 6 | D24: 6 | E24: 7 | F24: 7 | G24: 7 | H24: 8 | I24: events | J24: Multiple official promo releases on sandiegogulls.com | K24: Public/Projection
A25: TICKETING | B25: STM entry price | C25: 476 | D25: 540 | E25: 540 | F25: 560 | G25: 614 | H25: =ROUND(G25*(1+$H$10),0) -> 632 | I25: $/seat | J25: Multiple official ticketing releases on sandiegogulls.com | K25: Public/Projection
A26: TICKETING | B26: Single-game floor (box office / public) | C26: 19 | D26: 21 | E26: 20 | F26: 22 | G26: 23 | H26: =ROUND(G26*(1+$H$11),0) -> 24 | I26: $/ticket | J26: Multiple official ticketing releases on sandiegogulls.com | K26: Public/Estimate/Projection
A27: TICKETING | B27: Single-game floor (online incl. fees) | F27: 27.5 | G27: 28.75 | H27: 29.75 | I27: $/ticket | J27: https://www.sandiegogulls.com/news/detail/single-game-tickets-available-now | K27: Estimate/Projection
A28: TICKETING | B28: College ticket price | G28: 17 | H28: 17.5 | I28: $/ticket | J28: https://www.sandiegogulls.com/tickets/college | K28: Public/Projection
A29: TICKETING | B29: Family pack price floor | G29: 130 | H29: 135 | I29: $/pack | J29: https://www.sandiegogulls.com/tickets/4-packs | K29: Public/Projection
A30: TICKETING | B30: Group minimum size | C30: 10 | D30: 10 | E30: 10 | F30: 10 | G30: 10 | H30: 10 | I30: tickets | J30: https://www.sandiegogulls.com/tickets/group-tickets | K30: Public/Context
A31: TICKETING | B31: Max mini-plan discount | C31: 0.15 | D31: 0.15 | E31: 0.2 | F31: 0.3 | G31: 0.3 | H31: 0.3 | I31: pct | J31: https://www.sandiegogulls.com/tickets/gulls-mini-plans | K31: Estimate/Projection
A32: TICKETING | B32: Weighted average ticket price (modeled) | C32: 22 | D32: 22.4 | E32: 23.4 | F32: 24.4 | G32: 25.4 | H32: =ROUND(G32*(1+$H$6),2) -> 26.21 | I32: $/ticket | J32: Model methodology | K32: Estimate/Projection
A33: TICKETING | B33: Group sales share of gate | C33: 0.16 | D33: 0.17 | E33: 0.18 | F33: 0.19 | G33: 0.2 | H33: 0.21 | I33: pct | J33: Model methodology | K33: Estimate/Projection
A34: TICKETING | B34: Premium seating yield (included in gate) | C34: 380000 | D34: 400000 | E34: 460000 | F34: 520000 | G34: 600000 | H34: 660000 | I34: $ | J34: Model methodology | K34: Estimate/Projection
A35: TICKETING | B35: STM base (full-season equivalents) | C35: 2300 | D35: 2350 | E35: 2450 | F35: 2550 | G35: 2700 | H35: 2780 | I35: FSE | J35: Model methodology | K35: Estimate/Projection
A36: TICKETING | B36: STM retention rate | C36: 0.77 | D36: 0.76 | E36: 0.78 | F36: 0.8 | G36: 0.82 | H36: 0.83 | I36: pct | J36: Model methodology | K36: Estimate/Projection
A37: ANCILLARY | B37: F&B per-cap gross | C37: 13 | D37: 13.4 | E37: 14 | F37: 14.8 | G37: 15.5 | H37: =ROUND(G37*(1+$H$8),2) -> 16 | I37: $/attendee | J37: Model methodology | K37: Estimate/Projection
A38: ANCILLARY | B38: Team concession commission rate | C38: 0.04 | D38: 0.04 | E38: 0.04 | F38: 0.04 | G38: 0.04 | H38: 0.04 | I38: pct | J38: Model methodology | K38: Estimate
A39: ANCILLARY | B39: Merchandise per-cap | C39: 3.6 | D39: 3.8 | E39: 4 | F39: 4.2 | G39: 4.5 | H39: =ROUND(G39*(1+$H$9),2) -> 4.7 | I39: $/attendee | J39: Model methodology | K39: Estimate/Projection
A40: ANCILLARY | B40: Parking fee assumption | C40: 15 | D40: 15 | E40: 15 | F40: 18 | G40: 20 | H40: 21 | I40: $/vehicle | J40: https://pechangaarenasd.com/plan-your-visit/directions-parking/ | K40: Estimate/Projection
A41: ANCILLARY | B41: Average auto occupancy | C41: 2.6 | D41: 2.6 | E41: 2.6 | F41: 2.5 | G41: 2.5 | H41: 2.5 | I41: persons/vehicle | J41: Model methodology | K41: Estimate
...

Sheet Master_Model
A1: ID | B1: Group | C1: Field | D1: Unit | E1: 2021-22 | F1: 2022-23 | G1: 2023-24 | H1: 2024-25 | I1: 2025-26 | J1: 2026-27 | K1: Status | L1: Confidence | M1: Primary Source / Method | N1: Notes
A2: 1. Fan Demand, Schedule & Ticketing
A3: 1 | B3: Fan Demand / Ticketing | C3: Average attendance | D3: fans/game | E3: =Assumptions!C13 -> 6992 | F3: =Assumptions!D13 -> 6953 | G3: =Assumptions!E13 -> 7249 | H3: =Assumptions!F13 -> 7262 | I3: =Assumptions!G13 -> 7403 | J3: =Assumptions!H13 -> 7625 | K3: Public input / projection | L3: High | M3: HockeyDB / official schedule | N3: 2026-27 baseline projected from 2025-26 using control.
A4: 2 | B4: Fan Demand / Ticketing | C4: Home games | D4: games | E4: =Assumptions!C14 -> 34 | F4: =Assumptions!D14 -> 36 | G4: =Assumptions!E14 -> 36 | H4: =Assumptions!F14 -> 36 | I4: =Assumptions!G14 -> 36 | J4: =Assumptions!H14 -> 36 | K4: Public input | L4: High | M4: Official schedules | N4: 2021-22 was 34 home games; subsequent seasons 36.
A5: 3 | B5: Fan Demand / Ticketing | C5: Total home attendance | D5: fans | E5: =E3*E4 -> 237728 | F5: =F3*F4 -> 250308 | G5: =G3*G4 -> 260964 | H5: =H3*H4 -> 261432 | I5: =I3*I4 -> 266508 | J5: =J3*J4 -> 274500 | K5: Derived | L5: High | M5: Attendance × home games | N5: Average attendance multiplied by home games.
A6: 4 | B6: Fan Demand / Ticketing | C6: Home weekend dates | D6: dates | E6: =Assumptions!C17 -> 23 | F6: =Assumptions!D17 -> 23 | G6: =Assumptions!E17 -> 26 | H6: =Assumptions!F17 -> 25 | I6: =Assumptions!G17 -> 25 | J6: =Assumptions!H17 -> 25 | K6: Public input | L6: High | M6: Official schedules | N6: Official yearly schedule releases.
A7: 5 | B7: Fan Demand / Ticketing | C7: Friday home games | D7: games | E7: =Assumptions!C18 -> 11 | F7: =Assumptions!D18 -> 12 | G7: =Assumptions!E18 -> 12 | H7: =Assumptions!F18 -> 9 | I7: =Assumptions!G18 -> 10 | J7: =Assumptions!H18 -> 10 | K7: Public input | L7: High | M7: Official schedules | N7: Official yearly schedule releases.
A8: 6 | B8: Fan Demand / Ticketing | C8: Saturday home games | D8: games | E8: =Assumptions!C19 -> 11 | F8: =Assumptions!D19 -> 11 | G8: =Assumptions!E19 -> 12 | H8: =Assumptions!F19 -> 14 | I8: =Assumptions!G19 -> 10 | J8: =Assumptions!H19 -> 11 | K8: Public input / projection | L8: High | M8: Official schedules | N8: 2026-27 baseline projected mix.
A9: 7 | B9: Fan Demand / Ticketing | C9: Sunday home games | D9: games | E9: =Assumptions!C20 -> 1 | F9: =Assumptions!D20 -> 1 | G9: =Assumptions!E20 -> 2 | H9: =Assumptions!F20 -> 2 | I9: =Assumptions!G20 -> 5 | J9: =Assumptions!H20 -> 4 | K9: Public input / projection | L9: High | M9: Official schedules | N9: 2026-27 baseline projected mix.
A10: 8 | B10: Fan Demand / Ticketing | C10: Back-to-back sets | D10: sets | E10: =Assumptions!C21 -> 24 | F10: =Assumptions!D21 -> 21 | G10: =Assumptions!E21 -> 18 | H10: =Assumptions!F21 -> 20 | I10: =Assumptions!G21 -> 22 | J10: =Assumptions!H21 -> 22 | K10: Public input | L10: High | M10: Official schedules | N10: Official yearly schedule releases.
A11: 9 | B11: Fan Demand / Ticketing | C11: Promotional / theme nights | D11: nights | E11: =Assumptions!C22 -> 13 | F11: =Assumptions!D22 -> 15 | G11: =Assumptions!E22 -> 16 | H11: =Assumptions!F22 -> 23 | I11: =Assumptions!G22 -> 28 | J11: =Assumptions!H22 -> 30 | K11: Public input / projection | L11: High | M11: Official promo releases | N11: 2025-26 includes 8 anniversary nights + 20 additional promotional nights.
A12: 10 | B12: Fan Demand / Ticketing | C12: Giveaway items | D12: items | E12: =Assumptions!C23 -> 7 | F12: =Assumptions!D23 -> 6 | G12: =Assumptions!E23 -> 10 | H12: =Assumptions!F23 -> 11 | I12: =Assumptions!G23 -> 5 | J12: =Assumptions!H23 -> 6 | K12: Public input / projection | L12: Medium | M12: Official promo releases | N12: 2025-26 current public list includes five announced giveaways.
A13: 11 | B13: Fan Demand / Ticketing | C13: Pregame tailgates | D13: events | E13: =Assumptions!C24 -> 6 | F13: =Assumptions!D24 -> 6 | G13: =Assumptions!E24 -> 7 | H13: =Assumptions!F24 -> 7 | I13: =Assumptions!G24 -> 7 | J13: =Assumptions!H24 -> 8 | K13: Public input / projection | L13: Medium | M13: Official promo releases | N13: Counted / projected from public promo schedules.
A14: 12 | B14: Fan Demand / Ticketing | C14: STM entry price | D14: $ | E14: =Assumptions!C25 -> 476 | F14: =Assumptions!D25 -> 540 | G14: =Assumptions!E25 -> 540 | H14: =Assumptions!F25 -> 560 | I14: =Assumptions!G25 -> 614 | J14: =Assumptions!H25 -> 632 | K14: Public input / projection | L14: High | M14: Official ticketing releases | N14: Gulls Elite floor price.
A15: 13 | B15: Fan Demand / Ticketing | C15: STM entry price per game | D15: $ | E15: =E14/E4 -> 14 | F15: =F14/F4 -> 15 | G15: =G14/G4 -> 15 | H15: =H14/H4 -> 15.555556 | I15: =I14/I4 -> 17.055556 | J15: =J14/J4 -> 17.555556 | K15: Derived | L15: High | M15: STM entry price ÷ home games | N15: Season-ticket floor divided by home games.
A16: 14 | B16: Fan Demand / Ticketing | C16: Single-game floor (box office / public) | D16: $ | E16: =Assumptions!C26 -> 19 | F16: =Assumptions!D26 -> 21 | G16: =Assumptions!E26 -> 20 | H16: =Assumptions!F26 -> 22 | I16: =Assumptions!G26 -> 23 | J16: =Assumptions!H26 -> 24 | K16: Public input / estimate / projection | L16: Medium | M16: Official ticketing releases | N16: 2024-25 floor is interpolated estimate.
A17: 15 | B17: Fan Demand / Ticketing | C17: Single-game floor (online incl. fees) | D17: $ | E17: =Assumptions!C27 -> 0 | F17: =Assumptions!D27 -> 0 | G17: =Assumptions!E27 -> 0 | H17: =Assumptions!F27 -> 27.5 | I17: =Assumptions!G27 -> 28.75 | J17: =Assumptions!H27 -> 29.75 | K17: Estimate / projection | L17: Medium | M17: Official 2025-26 ticketing release | N17: 2025-26 is official; 2024-25 and 2026-27 are modeled estimates.
A18: 16 | B18: Fan Demand / Ticketing | C18: College ticket price | D18: $ | E18: =Assumptions!C28 -> 0 | F18: =Assumptions!D28 -> 0 | G18: =Assumptions!E28 -> 0 | H18: =Assumptions!F28 -> 0 | I18: =Assumptions!G28 -> 17 | J18: =Assumptions!H28 -> 17.5 | K18: Public input / projection | L18: Medium | M18: Official college page | N18: Current season official price.
A19: 17 | B19: Fan Demand / Ticketing | C19: Family pack price floor | D19: $ | E19: =Assumptions!C29 -> 0 | F19: =Assumptions!D29 -> 0 | G19: =Assumptions!E29 -> 0 | H19: =Assumptions!F29 -> 0 | I19: =Assumptions!G29 -> 130 | J19: =Assumptions!H29 -> 135 | K19: Public input / projection | L19: Medium | M19: Official family-pack page | N19: Current-season official product.
A20: 18 | B20: Fan Demand / Ticketing | C20: Group minimum size | D20: tickets | E20: =Assumptions!C30 -> 10 | F20: =Assumptions!D30 -> 10 | G20: =Assumptions!E30 -> 10 | H20: =Assumptions!F30 -> 10 | I20: =Assumptions!G30 -> 10 | J20: =Assumptions!H30 -> 10 | K20: Public / context | L20: Medium | M20: Official group page | N20: Assumed stable historically.
A21: 19 | B21: Fan Demand / Ticketing | C21: Max mini-plan discount | D21: pct | E21: =Assumptions!C31 -> 0.15 | F21: =Assumptions!D31 -> 0.15 | G21: =Assumptions!E31 -> 0.2 | H21: =Assumptions!F31 -> 0.3 | I21: =Assumptions!G31 -> 0.3 | J21: =Assumptions!H31 -> 0.3 | K21: Estimate / projection | L21: Low | M21: Public current mini-plan page | N21: Historical values are conservative placeholders.
A22: 20 | B22: Fan Demand / Ticketing | C22: Weighted average ticket price (modeled) | D22: $ | E22: =Assumptions!C32 -> 22 | F22: =Assumptions!D32 -> 22.4 | G22: =Assumptions!E32 -> 23.4 | H22: =Assumptions!F32 -> 24.4 | I22: =Assumptions!G32 -> 25.4 | J22: =Assumptions!H32 -> 26.21 | K22: Estimate / projection | L22: Medium | M22: Model methodology | N22: Modeled from ticket product mix and public price anchors.
A23: 21 | B23: Fan Demand / Ticketing | C23: Group sales share of gate | D23: pct | E23: =Assumptions!C33 -> 0.16 | F23: =Assumptions!D33 -> 0.17 | G23: =Assumptions!E33 -> 0.18 | H23: =Assumptions!F33 -> 0.19 | I23: =Assumptions!G33 -> 0.2 | J23: =Assumptions!H33 -> 0.21 | K23: Estimate / projection | L23: Low | M23: Model methodology | N23: Logical range based on minor-league group channel importance.
A24: 22 | B24: Fan Demand / Ticketing | C24: Premium seating yield | D24: $ | E24: =Assumptions!C34 -> 380000 | F24: =Assumptions!D34 -> 400000 | G24: =Assumptions!E34 -> 460000 | H24: =Assumptions!F34 -> 520000 | I24: =Assumptions!G34 -> 600000 | J24: =Assumptions!H34 -> 660000 | K24: Estimate / projection | L24: Low | M24: Model methodology | N24: Embedded within gate yield; not additive in revenue total.
A25: 23 | B25: Fan Demand / Ticketing | C25: STM base (FSE) | D25: FSE | E25: =Assumptions!C35 -> 2300 | F25: =Assumptions!D35 -> 2350 | G25: =Assumptions!E35 -> 2450 | H25: =Assumptions!F35 -> 2550 | I25: =Assumptions!G35 -> 2700 | J25: =Assumptions!H35 -> 2780 | K25: Estimate / projection | L25: Low | M25: Model methodology | N25: Modeled from attendance and ticket mix.
A26: 24 | B26: Fan Demand / Ticketing | C26: STM retention rate | D26: pct | E26: =Assumptions!C36 -> 0.77 | F26: =Assumptions!D36 -> 0.76 | G26: =Assumptions!E36 -> 0.78 | H26: =Assumptions!F36 -> 0.8 | I26: =Assumptions!G36 -> 0.82 | J26: =Assumptions!H36 -> 0.83 | K26: Estimate / projection | L26: Low | M26: Model methodology | N26: Modeled range.
A27: 2. Revenue Engine & Economics
A28: 25 | B28: Revenue Engine | C28: Gate revenue | D28: $ | E28: =E5*E22 -> 5230016 | F28: =F5*F22 -> 5606899.2 | G28: =G5*G22 -> 6106557.6 | H28: =H5*H22 -> 6378940.8 | I28: =I5*I22 -> 6769303.2 | J28: =J5*J22 -> 7194645 | K28: Derived | L28: Medium | M28: Total attendance × WATP | N28: Modeled gate revenue using weighted average ticket price.
A29: 26 | B29: Revenue Engine | C29: Facility fee per paid ticket | D29: $ | E29: =Assumptions!C57 -> 0 | F29: =Assumptions!D57 -> 0 | G29: =Assumptions!E57 -> 2.5 | H29: =Assumptions!F57 -> 3 | I29: =Assumptions!G57 -> 3 | J29: =Assumptions!H57 -> 3 | K29: Estimate | L29: Low | M29: Lease-era reporting / model assumption | N29: Publicly discussed current surcharge structure; early years not confirmed.
A30: 27 | B30: Revenue Engine | C30: Facility fee liability | D30: $ | E30: =IFERROR(E5*E29,"") -> 0 | F30: =IFERROR(F5*F29,"") -> 0 | G30: =IFERROR(G5*G29,"") -> 652410 | H30: =IFERROR(H5*H29,"") -> 784296 | I30: =IFERROR(I5*I29,"") -> 799524 | J30: =IFERROR(J5*J29,"") -> 823500 | K30: Derived | L30: Low | M30: Total attendance × facility fee | N30: Pass-through city/venue fee liability estimate.
A31: 28 | B31: Revenue Engine | C31: Revenue per available seat (RevPAS) | D31: $ | E31: =IFERROR(E28/(E53*E4),"") -> 11.905882 | F31: =IFERROR(F28/(F53*F4),"") -> 12.054737 | G31: =IFERROR(G28/(G53*G4),"") -> 13.128994 | H31: =IFERROR(H28/(H53*H4),"") -> 13.714613 | I31: =IFERROR(I28/(I53*I4),"") -> 14.553885 | J31: =IFERROR(J28/(J53*J4),"") -> 15.468363 | K31: Derived | L31: Medium | M31: Gate ÷ (capacity × home games) | N31: Uses 12,920 hockey capacity.
A32: 29 | B32: Revenue Engine | C32: F&B per-cap gross | D32: $ | E32: =Assumptions!C37 -> 13 | F32: =Assumptions!D37 -> 13.4 | G32: =Assumptions!E37 -> 14 | H32: =Assumptions!F37 -> 14.8 | I32: =Assumptions!G37 -> 15.5 | J32: =Assumptions!H37 -> 16 | K32: Estimate / projection | L32: Low | M32: Model methodology | N32: Gross in-building spend, not team net.
A33: 30 | B33: Revenue Engine | C33: Team concession commission rate | D33: pct | E33: =Assumptions!C38 -> 0.04 | F33: =Assumptions!D38 -> 0.04 | G33: =Assumptions!E38 -> 0.04 | H33: =Assumptions!F38 -> 0.04 | I33: =Assumptions!G38 -> 0.04 | J33: =Assumptions!H38 -> 0.04 | K33: Estimate | L33: Low | M33: Model methodology | N33: Private split; modeled nominal rate.
A34: 31 | B34: Revenue Engine | C34: Concession commission revenue | D34: $ | E34: =E5*E32*E33 -> 123618.56 | F34: =F5*F32*F33 -> 134165.09 | G34: =G5*G32*G33 -> 146139.84 | H34: =H5*H32*H33 -> 154767.74 | I34: =I5*I32*I33 -> 165234.96 | J34: =J5*J32*J33 -> 175680 | K34: Derived | L34: Low | M34: Attendance × F&B per-cap × commission rate | N34: Team-side concession revenue estimate.
A35: 32 | B35: Revenue Engine | C35: Merchandise per-cap | D35: $ | E35: =Assumptions!C39 -> 3.6 | F35: =Assumptions!D39 -> 3.8 | G35: =Assumptions!E39 -> 4 | H35: =Assumptions!F39 -> 4.2 | I35: =Assumptions!G39 -> 4.5 | J35: =Assumptions!H39 -> 4.7 | K35: Estimate / projection | L35: Low | M35: Model methodology | N35: Modeled team-store spend per attendee.
A36: 33 | B36: Revenue Engine | C36: Merchandise revenue | D36: $ | E36: =E5*E35 -> 855820.8 | F36: =F5*F35 -> 951170.4 | G36: =G5*G35 -> 1043856 | H36: =H5*H35 -> 1098014.4 | I36: =I5*I35 -> 1199286 | J36: =J5*J35 -> 1290150 | K36: Derived | L36: Low | M36: Attendance × merch per-cap | N36: Modeled gross merchandise revenue.
A37: 34 | B37: Revenue Engine | C37: Parking fee assumption | D37: $ | E37: =Assumptions!C40 -> 15 | F37: =Assumptions!D40 -> 15 | G37: =Assumptions!E40 -> 15 | H37: =Assumptions!F40 -> 18 | I37: =Assumptions!G40 -> 20 | J37: =Assumptions!H40 -> 21 | K37: Estimate / projection | L37: Low | M37: Public parking page + model | N37: Event-specific public fee structure; year values are model anchors.
A38: 35 | B38: Revenue Engine | C38: Average auto occupancy | D38: persons | E38: =Assumptions!C41 -> 2.6 | F38: =Assumptions!D41 -> 2.6 | G38: =Assumptions!E41 -> 2.6 | H38: =Assumptions!F41 -> 2.5 | I38: =Assumptions!G41 -> 2.5 | J38: =Assumptions!H41 -> 2.5 | K38: Estimate | L38: Low | M38: Model methodology | N38: Transport assumption for parking yield.
A39: 36 | B39: Revenue Engine | C39: Team share of parking | D39: pct | E39: =Assumptions!C42 -> 0.05 | F39: =Assumptions!D42 -> 0.05 | G39: =Assumptions!E42 -> 0.05 | H39: =Assumptions!F42 -> 0.05 | I39: =Assumptions!G42 -> 0.05 | J39: =Assumptions!H42 -> 0.05 | K39: Estimate | L39: Low | M39: Model methodology | N39: No public split located; nominal placeholder only.
A40: 37 | B40: Revenue Engine | C40: Parking revenue yield | D40: $ | E40: =IFERROR((E5/E38)*E37*E39,"") -> 68575.385 | F40: =IFERROR((F5/F38)*F37*F39,"") -> 72204.231 | G40: =IFERROR((G5/G38)*G37*G39,"") -> 75278.077 | H40: =IFERROR((H5/H38)*H37*H39,"") -> 94115.52 | I40: =IFERROR((I5/I38)*I37*I39,"") -> 106603.2 | J40: =IFERROR((J5/J38)*J37*J39,"") -> 115290 | K40: Derived | L40: Low | M40: Attendance ÷ occupancy × fee × share | N40: Team-side parking estimate.
...

Sheet Scenario_OnePager
A1: 2026-27 Projection Upside — Revenue, EBITDA & Value Creation Levers
A2: Baseline uses the Master_Model. Scenario columns show how disciplined operations, pricing, sponsorship and digital execution can move the club to a higher operating ceiling.
A4: Baseline Revenue | D4: Baseline EBITDA | G4: Baseline Valuation | J4: Baseline Attendance
A5: =Master_Model!J49 -> 12031865 | D5: =Master_Model!J95 -> 1682309 | G5: =Master_Model!J99 -> 38501968 | J5: =Master_Model!J3 -> 7625
A8: Lever / Output | B8: Efficiency / Ops | C8: Sales & Retention | D8: Premium + Sponsorship | F8: Recommended Actions to Push the Curve Higher
A9: Attendance uplift | B9: 0.02 | C9: 0.04 | D9: 0.06 | F9: 1) OPERATIONS / CRM CLEAN-UP • Remove stale ticket copy and unify current-season pricing across pages. • Standardize lead-source tagging and post-game follow-up windows. • Weekly dashboard: STM churn, second-game conversion, group close rate, per-cap spend.
A10: WATP uplift | B10: 0.015 | C10: 0.025 | D10: 0.04
A11: Per-cap uplift | B11: 0.03 | C11: 0.05 | D11: 0.07
A12: Sponsorship uplift | B12: 0.04 | C12: 0.08 | D12: 0.12
A13: EBITDA margin uplift | B13: 0.003 | C13: 0.006 | D13: 0.01 | F13: 2) SALES & RETENTION ENGINE • Build first-game-to-second-game journeys for single-game, student and family-pack buyers. • Expand military, youth sports and corporate group calendars around promo nights. • Tighten STM save offers 60–90 days before renewal deadlines.
A16: Lever / Output | B16: Efficiency / Ops | C16: Sales & Retention | D16: Premium + Sponsorship
A17: Projected attendance | B17: =ROUND(Master_Model!J3*(1+B9),0) -> 7778 | C17: =ROUND(Master_Model!J3*(1+C9),0) -> 7930 | D17: =ROUND(Master_Model!J3*(1+D9),0) -> 8083 | F17: 3) PREMIUM / SPONSORSHIP / DIGITAL • Package Stella Lounge, suites and premium parking into higher-yield bundles. • Sell more digital presented-by inventory across app, email and social. • Expand bar-network and watch-party capture into lead generation, not just branding.
A18: Projected WATP | B18: =Master_Model!J22*(1+B10) -> 26.60315 | C18: =Master_Model!J22*(1+C10) -> 26.86525 | D18: =Master_Model!J22*(1+D10) -> 27.2584
A19: Projected per-cap | B19: =Master_Model!J41*(1+B11) -> 21.321 | C19: =Master_Model!J41*(1+C11) -> 21.735 | D19: =Master_Model!J41*(1+D11) -> 22.149
A20: Projected sponsorship | B20: =Master_Model!J42*(1+B12) -> 3069144 | C20: =Master_Model!J42*(1+C12) -> 3187188 | D20: =Master_Model!J42*(1+D12) -> 3305232
A21: Incremental gate revenue | B21: =(B17*Master_Model!J4*B18)-Master_Model!J28 -> 254449.83 | C21: =(C17*Master_Model!J4*C18)-Master_Model!J28 -> 474846.57 | D21: =(D17*Master_Model!J4*D18)-Master_Model!J28 -> 737222.3
A22: Incremental ancillary revenue | B22: =(B17*Master_Model!J4*B19)-(Master_Model!J5*Master_Model!J41) -> 287900.57 | C22: =(C17*Master_Model!J4*C19)-(Master_Model!J5*Master_Model!J41) -> 522757.8 | D22: =(D17*Master_Model!J4*D19)-(Master_Model!J5*Master_Model!J41) -> 762943.21
A23: Incremental sponsorship | B23: =B20-Master_Model!J42 -> 118044 | C23: =C20-Master_Model!J42 -> 236088 | D23: =D20-Master_Model!J42 -> 354132
A24: Total incremental revenue | B24: =SUM(B21:B23) -> 660394.39 | C24: =SUM(C21:C23) -> 1233692.4 | D24: =SUM(D21:D23) -> 1854297.5
A25: Projected total revenue | B25: =Master_Model!J49+B24 -> 12692259 | C25: =Master_Model!J49+C24 -> 13265557 | D25: =Master_Model!J49+D24 -> 13886163
A26: Projected EBITDA | B26: =B25*(Master_Model!J94+B13) -> 1812722.9 | C26: =C25*(Master_Model!J94+C13) -> 1934398.6 | D26: =D25*(Master_Model!J94+D13) -> 2080440.6
A27: Projected valuation | B27: =B25*Master_Model!J98 -> 40615230 | C27: =C25*Master_Model!J98 -> 42449784 | D27: =D25*Master_Model!J98 -> 44435720

Sheet Source_Log
A1: Column1 | B1: Category | C1: 2021-22 | D1: 2022-23 | E1: 2023-24 | F1: 2024-25 | G1: 2025-26 | H1: 2026-27 | I1: Unit | J1: Source / Method | K1: Status
A2: 2026-27 attendance growth assumption | B2: CONTROL | H2: 0.03 | I2: pct | J2: Model control | K2: Control
A3: 2026-27 WATP growth assumption | B3: CONTROL | H3: 0.032 | I3: pct | J3: Model control | K3: Control
A4: 2026-27 sponsorship growth assumption | B4: CONTROL | H4: 0.093 | I4: pct | J4: Model control | K4: Control
A5: 2026-27 per-cap F&B growth assumption | B5: CONTROL | H5: 0.032 | I5: pct | J5: Model control | K5: Control
A6: 2026-27 merch per-cap growth assumption | B6: CONTROL | H6: 0.044 | I6: pct | J6: Model control | K6: Control
A7: 2026-27 STM price growth assumption | B7: CONTROL | H7: 0.03 | I7: pct | J7: Model control | K7: Control
A8: 2026-27 single-game price growth assumption | B8: CONTROL | H8: 0.043 | I8: pct | J8: Model control | K8: Control
A9: 2026-27 website traffic growth assumption | B9: CONTROL | H9: 0.08 | I9: pct | J9: Model control | K9: Control
A10: Average attendance | B10: ATTENDANCE | C10: 6992 | D10: 6953 | E10: 7249 | F10: 7262 | G10: 7403 | I10: fans/game | J10: https://www.hockeydb.com/stte/san-diego-gulls-11619.html | K10: Public/Projection
A11: Home games | B11: ATTENDANCE | C11: 34 | D11: 36 | E11: 36 | F11: 36 | G11: 36 | H11: 36 | I11: games | J11: https://www.sandiegogulls.com/news/detail/san-diego-gulls-2021-22-schedule-announced | K11: Public
A12: Hockey seating capacity | B12: VENUE | C12: 12920 | D12: 12920 | E12: 12920 | F12: 12920 | G12: 12920 | H12: 12920 | I12: seats | J12: https://www.sandiegogulls.com/assets/doc/2021-22-San-Diego-Gulls-Media-Guide-compressed-92470e4558.pdf | K12: Context
A13: General venue capacity | B13: VENUE | C13: 14000 | D13: 14000 | E13: 14000 | F13: 14000 | G13: 14000 | H13: 14000 | I13: seats | J13: https://pechangaarenasd.com/about/ | K13: Public
A14: Home weekend dates | B14: SCHEDULE | C14: 23 | D14: 23 | E14: 26 | F14: 25 | G14: 25 | H14: 25 | I14: dates | J14: Multiple official schedule releases on sandiegogulls.com | K14: Public
A15: Friday home games | B15: SCHEDULE | C15: 11 | D15: 12 | E15: 12 | F15: 9 | G15: 10 | H15: 10 | I15: games | J15: Multiple official schedule releases on sandiegogulls.com | K15: Public
A16: Saturday home games | B16: SCHEDULE | C16: 11 | D16: 11 | E16: 12 | F16: 14 | G16: 10 | H16: 11 | I16: games | J16: Multiple official schedule releases on sandiegogulls.com | K16: Public/Projection
A17: Sunday home games | B17: SCHEDULE | C17: 1 | D17: 1 | E17: 2 | F17: 2 | G17: 5 | H17: 4 | I17: games | J17: Multiple official schedule releases on sandiegogulls.com | K17: Public/Projection
A18: Back-to-back sets | B18: SCHEDULE | C18: 24 | D18: 21 | E18: 18 | F18: 20 | G18: 22 | H18: 22 | I18: sets | J18: Multiple official schedule releases on sandiegogulls.com | K18: Public
A19: Promotional/theme nights announced | B19: MARKETING | C19: 13 | D19: 15 | E19: 16 | F19: 23 | G19: 28 | H19: 30 | I19: nights | J19: Multiple official promo releases on sandiegogulls.com | K19: Public/Projection
A20: Giveaway items announced | B20: MARKETING | C20: 7 | D20: 6 | E20: 10 | F20: 11 | G20: 5 | H20: 6 | I20: items | J20: Multiple official promo releases on sandiegogulls.com | K20: Public/Projection
A21: Pregame tailgates | B21: MARKETING | C21: 6 | D21: 6 | E21: 7 | F21: 7 | G21: 7 | H21: 8 | I21: events | J21: Multiple official promo releases on sandiegogulls.com | K21: Public/Projection
A22: STM entry price | B22: TICKETING | C22: 476 | D22: 540 | E22: 540 | F22: 560 | G22: 614 | I22: $/seat | J22: Multiple official ticketing releases on sandiegogulls.com | K22: Public/Projection
A23: Single-game floor (box office / public) | B23: TICKETING | C23: 19 | D23: 21 | E23: 20 | F23: 22 | G23: 23 | I23: $/ticket | J23: Multiple official ticketing releases on sandiegogulls.com | K23: Public/Estimate/Projection
A24: Single-game floor (online incl. fees) | B24: TICKETING | F24: 27.5 | G24: 28.75 | H24: 29.75 | I24: $/ticket | J24: https://www.sandiegogulls.com/news/detail/single-game-tickets-available-now | K24: Estimate/Projection
A25: College ticket price | B25: TICKETING | G25: 17 | H25: 17.5 | I25: $/ticket | J25: https://www.sandiegogulls.com/tickets/college | K25: Public/Projection
A26: Family pack price floor | B26: TICKETING | G26: 130 | H26: 135 | I26: $/pack | J26: https://www.sandiegogulls.com/tickets/4-packs | K26: Public/Projection
A27: Group minimum size | B27: TICKETING | C27: 10 | D27: 10 | E27: 10 | F27: 10 | G27: 10 | H27: 10 | I27: tickets | J27: https://www.sandiegogulls.com/tickets/group-tickets | K27: Public/Context
A28: Max mini-plan discount | B28: TICKETING | C28: 0.15 | D28: 0.15 | E28: 0.2 | F28: 0.3 | G28: 0.3 | H28: 0.3 | I28: pct | J28: https://www.sandiegogulls.com/tickets/gulls-mini-plans | K28: Estimate/Projection
A29: Weighted average ticket price (modeled) | B29: TICKETING | C29: 22 | D29: 22.4 | E29: 23.4 | F29: 24.4 | G29: 25.4 | I29: $/ticket | J29: Model methodology | K29: Estimate/Projection
A30: Group sales share of gate | B30: TICKETING | C30: 0.16 | D30: 0.17 | E30: 0.18 | F30: 0.19 | G30: 0.2 | H30: 0.21 | I30: pct | J30: Model methodology | K30: Estimate/Projection
A31: Premium seating yield (included in gate) | B31: TICKETING | C31: 380000 | D31: 400000 | E31: 460000 | F31: 520000 | G31: 600000 | H31: 660000 | I31: $ | J31: Model methodology | K31: Estimate/Projection
A32: STM base (full-season equivalents) | B32: TICKETING | C32: 2300 | D32: 2350 | E32: 2450 | F32: 2550 | G32: 2700 | H32: 2780 | I32: FSE | J32: Model methodology | K32: Estimate/Projection
A33: STM retention rate | B33: TICKETING | C33: 0.77 | D33: 0.76 | E33: 0.78 | F33: 0.8 | G33: 0.82 | H33: 0.83 | I33: pct | J33: Model methodology | K33: Estimate/Projection
A34: F&B per-cap gross | B34: ANCILLARY | C34: 13 | D34: 13.4 | E34: 14 | F34: 14.8 | G34: 15.5 | I34: $/attendee | J34: Model methodology | K34: Estimate/Projection
A35: Team concession commission rate | B35: ANCILLARY | C35: 0.04 | D35: 0.04 | E35: 0.04 | F35: 0.04 | G35: 0.04 | H35: 0.04 | I35: pct | J35: Model methodology | K35: Estimate
A36: Merchandise per-cap | B36: ANCILLARY | C36: 3.6 | D36: 3.8 | E36: 4 | F36: 4.2 | G36: 4.5 | I36: $/attendee | J36: Model methodology | K36: Estimate/Projection
A37: Parking fee assumption | B37: ANCILLARY | C37: 15 | D37: 15 | E37: 15 | F37: 18 | G37: 20 | H37: 21 | I37: $/vehicle | J37: https://pechangaarenasd.com/plan-your-visit/directions-parking/ | K37: Estimate/Projection
A38: Average auto occupancy | B38: ANCILLARY | C38: 2.6 | D38: 2.6 | E38: 2.6 | F38: 2.5 | G38: 2.5 | H38: 2.5 | I38: persons/vehicle | J38: Model methodology | K38: Estimate
A39: Team share of parking | B39: ANCILLARY | C39: 0.05 | D39: 0.05 | E39: 0.05 | F39: 0.05 | G39: 0.05 | H39: 0.05 | I39: pct | J39: Model methodology | K39: Estimate
A40: Total sponsorship revenue | B40: SPONSORSHIP | C40: 1950000 | D40: 2000000 | E40: 2200000 | F40: 2450000 | G40: 2700000 | I40: $ | J40: Model methodology | K40: Estimate/Projection
...

Sheet Charts
A1: Column1 | B1: 2021-22 | C1: 2022-23 | D1: 2023-24 | E1: 2024-25 | F1: 2025-26 | G1: 2026-27
A2: Average Attendance | B2: =Master_Model!E3 -> 6992 | C2: =Master_Model!F3 -> 6953 | D2: =Master_Model!G3 -> 7249 | E2: =Master_Model!H3 -> 7262 | F2: =Master_Model!I3 -> 7403 | G2: =Master_Model!J3 -> 7625
A3: Gross Revenue | B3: =Master_Model!E49 -> 8458030.7 | C3: =Master_Model!F49 -> 8954438.9 | D3: =Master_Model!G49 -> 9771831.5 | E3: =Master_Model!H49 -> 10405838 | F3: =Master_Model!I49 -> 11210427 | G3: =Master_Model!J49 -> 12031865
A4: EBITDA | B4: =Master_Model!E95 -> 899263.74 | C4: =Master_Model!F95 -> 1112461.9 | D4: =Master_Model!G95 -> 733312.52 | E4: =Master_Model!H95 -> 943447.46 | F4: =Master_Model!I95 -> 1246049.4 | G4: =Master_Model!J95 -> 1682309
A5: Implied Valuation | B5: =Master_Model!E99 -> 27065698 | C5: =Master_Model!F99 -> 28654205 | D5: =Master_Model!G99 -> 31269861 | E5: =Master_Model!H99 -> 33298683 | F5: =Master_Model!I99 -> 35873368 | G5: =Master_Model!J99 -> 38501968
A8: Scenario | B8: Baseline | C8: Efficiency / Ops | D8: Sales & Retention | E8: Premium + Sponsorship
A9: Revenue | B9: =Master_Model!J49 -> 12031865 | C9: =Scenario_OnePager!B25 -> 12692259 | D9: =Scenario_OnePager!C25 -> 13265557 | E9: =Scenario_OnePager!D25 -> 13886163
A10: EBITDA | B10: =Master_Model!J95 -> 1682309 | C10: =Scenario_OnePager!B26 -> 1812722.9 | D10: =Scenario_OnePager!C26 -> 1934398.6 | E10: =Scenario_OnePager!D26 -> 2080440.6
