Workbook
Name Dashboard_Scenario_Input: 'Executive_Dashboard'!$C$3
Name Scenario_Selector: 'Assumptions'!$B$5
Name Attendance_Growth_Rate: 'Assumptions'!$B$6
Name WATP_Growth_Rate: 'Assumptions'!$B$7
Name Sponsorship_Growth_Rate: 'Assumptions'!$B$8
Name FB_Growth_Rate: 'Assumptions'!$B$9
Name Merch_Growth_Rate: 'Assumptions'!$B$10
Name STM_Growth_Rate: 'Assumptions'!$B$11
Name Single_Game_Growth_Rate: 'Assumptions'!$B$12
Name Website_Growth_Rate: 'Assumptions'!$B$13

Sheet Executive_Dashboard
B1: SAN DIEGO GULLS — EXECUTIVE DASHBOARD
B2: 2021-22 to 2026-27 forensic operating model | public anchors + interactive scenario planning
B3: Scenario | C3: Baseline | E3: Model status | F3: Live / scenario-linked
B5: Projected FY27 Revenue | E5: EBITDA Margin % | H5: Implied Franchise Value | K5: Attendance Capacity %
B6: =IFERROR(Master_Model!$J$52,0) | E6: =IFERROR(Master_Model!$J$97,0) | H6: =IFERROR(Master_Model!$J$102,0) | K6: =IFERROR(Master_Model!$J$6/Assumptions!$H$26,0)
B11: Open Scenario Levers | E11: Open Benchmarks | H11: Open Assumptions | K11: Open Source Log
B14: Executive readout • Attendance recovered from 6,992 (FY22) to 7,403 (FY26). • Private economics remain labeled as modeled estimates. • Changing the scenario switch updates FY27 revenue, EBITDA, valuation, and charts instantly. • Tactical upside comes from demand generation, ticket yield, sponsorship packaging, and digital conversion. | H14: What makes this decision-ready • Inputs and formulas are separated. • Scenario controls are validated and protected. • Master_Model is hidden for executive use but available for audit. • One-pager includes operational impact and competitor benchmarking. • Key assumption cells carry URL comments for auditability.
A23: Metric | B23: 2021-22 | C23: 2022-23 | D23: 2023-24 | E23: 2024-25 | F23: 2025-26 | G23: 2026-27
A24: Attendance | B24: =IFERROR(Master_Model!E6,0) | C24: =IFERROR(Master_Model!F6,0) | D24: =IFERROR(Master_Model!G6,0) | E24: =IFERROR(Master_Model!H6,0) | F24: =IFERROR(Master_Model!I6,0) | G24: =IFERROR(Master_Model!J6,0)
A25: Revenue | B25: =IFERROR(Master_Model!E52,0) | C25: =IFERROR(Master_Model!F52,0) | D25: =IFERROR(Master_Model!G52,0) | E25: =IFERROR(Master_Model!H52,0) | F25: =IFERROR(Master_Model!I52,0) | G25: =IFERROR(Master_Model!J52,0)
A26: EBITDA | B26: =IFERROR(Master_Model!E98,0) | C26: =IFERROR(Master_Model!F98,0) | D26: =IFERROR(Master_Model!G98,0) | E26: =IFERROR(Master_Model!H98,0) | F26: =IFERROR(Master_Model!I98,0) | G26: =IFERROR(Master_Model!J98,0)
A27: Valuation | B27: =IFERROR(Master_Model!E102,0) | C27: =IFERROR(Master_Model!F102,0) | D27: =IFERROR(Master_Model!G102,0) | E27: =IFERROR(Master_Model!H102,0) | F27: =IFERROR(Master_Model!I102,0) | G27: =IFERROR(Master_Model!J102,0)

Sheet Assumptions
A1: San Diego Gulls — Assumptions, Controls & Public Inputs
A2: Executive control lives on the dashboard. Yellow cells are editable scenario rates. The 2026-27 column is formula-driven and scenario-sensitive.
A4: Scenario Control | F4: Scenario Rate Matrix
A5: Scenario Selector (mirrors dashboard) | B5: =Executive_Dashboard!$C$3 | F5: Driver | G5: Baseline | H5: Tactical Upside | I5: Aggressive Growth | J5: Strategic Use
A6: Attendance growth | B6: =IF(Scenario_Selector="Baseline",$G6,IF(Scenario_Selector="Tactical Upside",$H6,$I6)) | F6: Attendance growth | G6: 0.03 | H6: 0.06 | I6: 0.09 | J6: Demand generation
A7: WATP growth | B7: =IF(Scenario_Selector="Baseline",$G7,IF(Scenario_Selector="Tactical Upside",$H7,$I7)) | F7: WATP growth | G7: 0.032 | H7: 0.05 | I7: 0.075 | J7: Ticket yield
A8: Sponsorship growth | B8: =IF(Scenario_Selector="Baseline",$G8,IF(Scenario_Selector="Tactical Upside",$H8,$I8)) | F8: Sponsorship growth | G8: 0.093 | H8: 0.12 | I8: 0.16 | J8: Sellable inventory
A9: F&B per-cap growth | B9: =IF(Scenario_Selector="Baseline",$G9,IF(Scenario_Selector="Tactical Upside",$H9,$I9)) | F9: F&B per-cap growth | G9: 0.032 | H9: 0.05 | I9: 0.07 | J9: Hospitality uplift
A10: Merch per-cap growth | B10: =IF(Scenario_Selector="Baseline",$G10,IF(Scenario_Selector="Tactical Upside",$H10,$I10)) | F10: Merch per-cap growth | G10: 0.044 | H10: 0.06 | I10: 0.08 | J10: Brand conversion
A11: STM entry growth | B11: =IF(Scenario_Selector="Baseline",$G11,IF(Scenario_Selector="Tactical Upside",$H11,$I11)) | F11: STM entry growth | G11: 0.03 | H11: 0.045 | I11: 0.06 | J11: Renewal ladder
A12: Single-game growth | B12: =IF(Scenario_Selector="Baseline",$G12,IF(Scenario_Selector="Tactical Upside",$H12,$I12)) | F12: Single-game growth | G12: 0.043 | H12: 0.06 | I12: 0.085 | J12: Dynamic pricing
A13: Website traffic growth | B13: =IF(Scenario_Selector="Baseline",$G13,IF(Scenario_Selector="Tactical Upside",$H13,$I13)) | F13: Website traffic growth | G13: 0.08 | H13: 0.12 | I13: 0.16 | J13: Digital funnel
A15: Category | B15: Driver | C15: 2021-22 | D15: 2022-23 | E15: 2023-24 | F15: 2024-25 | G15: 2025-26 | H15: 2026-27
A16: CONTROL | B16: 2026-27 attendance growth assumption | H16: 0.03
A17: CONTROL | B17: 2026-27 WATP growth assumption | H17: 0.032
A18: CONTROL | B18: 2026-27 sponsorship growth assumption | H18: 0.093
A19: CONTROL | B19: 2026-27 per-cap F&B growth assumption | H19: 0.032
A20: CONTROL | B20: 2026-27 merch per-cap growth assumption | H20: 0.044
A21: CONTROL | B21: 2026-27 STM price growth assumption | H21: 0.03
A22: CONTROL | B22: 2026-27 single-game price growth assumption | H22: 0.043
A23: CONTROL | B23: 2026-27 website traffic growth assumption | H23: 0.08
A24: ATTENDANCE | B24: Average attendance | C24: 6992 | D24: 6953 | E24: 7249 | F24: 7262 | G24: 7403 | H24: =ROUND(G24*(1+Attendance_Growth_Rate),0)
A25: ATTENDANCE | B25: Home games | C25: 34 | D25: 36 | E25: 36 | F25: 36 | G25: 36 | H25: 36
A26: VENUE | B26: Hockey seating capacity | C26: 12920 | D26: 12920 | E26: 12920 | F26: 12920 | G26: 12920 | H26: 12920
A27: VENUE | B27: General venue capacity | C27: 14000 | D27: 14000 | E27: 14000 | F27: 14000 | G27: 14000 | H27: 14000
A28: SCHEDULE | B28: Home weekend dates | C28: 23 | D28: 23 | E28: 26 | F28: 25 | G28: 25 | H28: 25
A29: SCHEDULE | B29: Friday home games | C29: 11 | D29: 12 | E29: 12 | F29: 9 | G29: 10 | H29: 10
A30: SCHEDULE | B30: Saturday home games | C30: 11 | D30: 11 | E30: 12 | F30: 14 | G30: 10 | H30: 11
A31: SCHEDULE | B31: Sunday home games | C31: 1 | D31: 1 | E31: 2 | F31: 2 | G31: 5 | H31: 4
A32: SCHEDULE | B32: Back-to-back sets | C32: 24 | D32: 21 | E32: 18 | F32: 20 | G32: 22 | H32: 22
A33: MARKETING | B33: Promotional/theme nights announced | C33: 13 | D33: 15 | E33: 16 | F33: 23 | G33: 28 | H33: 30
A34: MARKETING | B34: Giveaway items announced | C34: 7 | D34: 6 | E34: 10 | F34: 11 | G34: 5 | H34: 6
A35: MARKETING | B35: Pregame tailgates | C35: 6 | D35: 6 | E35: 7 | F35: 7 | G35: 7 | H35: 8
A36: TICKETING | B36: STM entry price | C36: 476 | D36: 540 | E36: 540 | F36: 560 | G36: 614 | H36: =ROUND(G36*(1+STM_Growth_Rate),0)
A37: TICKETING | B37: Single-game floor (box office / public) | C37: 19 | D37: 21 | E37: 20 | F37: 22 | G37: 23 | H37: =ROUND(G37*(1+Single_Game_Growth_Rate),0)
A38: TICKETING | B38: Single-game floor (online incl. fees) | F38: 27.5 | G38: 28.75 | H38: =ROUND(G38*(1+Single_Game_Growth_Rate),2)
A39: TICKETING | B39: College ticket price | G39: 17 | H39: =ROUND(G39*1.03,2)
A40: TICKETING | B40: Family pack price floor | G40: 130 | H40: =ROUND(G40*1.04,0)
A41: TICKETING | B41: Group minimum size | C41: 10 | D41: 10 | E41: 10 | F41: 10 | G41: 10 | H41: 10
A42: TICKETING | B42: Max mini-plan discount | C42: 0.15 | D42: 0.15 | E42: 0.2 | F42: 0.3 | G42: 0.3 | H42: 0.3
...

Sheet Master_Model
A1: San Diego Gulls — Forensic Financial, Operational & Marketing Model (FY2021-22 to FY2026-27)
A2: Public numbers are linked back to the Assumptions tab. Private figures are explicitly modeled estimates or logical ranges translated into a base-case value.
A4: ID | B4: Group | C4: Field | D4: Unit | E4: 2021-22 | F4: 2022-23 | G4: 2023-24 | H4: 2024-25 | I4: 2025-26 | J4: 2026-27 | K4: Status | L4: Confidence | M4: Primary Source / Method | N4: Notes
A5: 1. Fan Demand, Schedule & Ticketing
A6: 1 | B6: Fan Demand / Ticketing | C6: Average attendance | D6: fans/game | E6: =Assumptions!C24 | F6: =Assumptions!D24 | G6: =Assumptions!E24 | H6: =Assumptions!F24 | I6: =Assumptions!G24 | J6: =Assumptions!H24 | K6: Public input / projection | L6: High | M6: HockeyDB / official schedule | N6: 2026-27 baseline projected from 2025-26 using control.
A7: 2 | B7: Fan Demand / Ticketing | C7: Home games | D7: games | E7: =Assumptions!C25 | F7: =Assumptions!D25 | G7: =Assumptions!E25 | H7: =Assumptions!F25 | I7: =Assumptions!G25 | J7: =Assumptions!H25 | K7: Public input | L7: High | M7: Official schedules | N7: 2021-22 was 34 home games; subsequent seasons 36.
A8: 3 | B8: Fan Demand / Ticketing | C8: Total home attendance | D8: fans | E8: =E6*E7 | F8: =F6*F7 | G8: =G6*G7 | H8: =H6*H7 | I8: =I6*I7 | J8: =J6*J7 | K8: Derived | L8: High | M8: Attendance × home games | N8: Average attendance multiplied by home games.
A9: 4 | B9: Fan Demand / Ticketing | C9: Home weekend dates | D9: dates | E9: =Assumptions!C28 | F9: =Assumptions!D28 | G9: =Assumptions!E28 | H9: =Assumptions!F28 | I9: =Assumptions!G28 | J9: =Assumptions!H28 | K9: Public input | L9: High | M9: Official schedules | N9: Official yearly schedule releases.
A10: 5 | B10: Fan Demand / Ticketing | C10: Friday home games | D10: games | E10: =Assumptions!C29 | F10: =Assumptions!D29 | G10: =Assumptions!E29 | H10: =Assumptions!F29 | I10: =Assumptions!G29 | J10: =Assumptions!H29 | K10: Public input | L10: High | M10: Official schedules | N10: Official yearly schedule releases.
A11: 6 | B11: Fan Demand / Ticketing | C11: Saturday home games | D11: games | E11: =Assumptions!C30 | F11: =Assumptions!D30 | G11: =Assumptions!E30 | H11: =Assumptions!F30 | I11: =Assumptions!G30 | J11: =Assumptions!H30 | K11: Public input / projection | L11: High | M11: Official schedules | N11: 2026-27 baseline projected mix.
A12: 7 | B12: Fan Demand / Ticketing | C12: Sunday home games | D12: games | E12: =Assumptions!C31 | F12: =Assumptions!D31 | G12: =Assumptions!E31 | H12: =Assumptions!F31 | I12: =Assumptions!G31 | J12: =Assumptions!H31 | K12: Public input / projection | L12: High | M12: Official schedules | N12: 2026-27 baseline projected mix.
A13: 8 | B13: Fan Demand / Ticketing | C13: Back-to-back sets | D13: sets | E13: =Assumptions!C32 | F13: =Assumptions!D32 | G13: =Assumptions!E32 | H13: =Assumptions!F32 | I13: =Assumptions!G32 | J13: =Assumptions!H32 | K13: Public input | L13: High | M13: Official schedules | N13: Official yearly schedule releases.
A14: 9 | B14: Fan Demand / Ticketing | C14: Promotional / theme nights | D14: nights | E14: =Assumptions!C33 | F14: =Assumptions!D33 | G14: =Assumptions!E33 | H14: =Assumptions!F33 | I14: =Assumptions!G33 | J14: =Assumptions!H33 | K14: Public input / projection | L14: High | M14: Official promo releases | N14: 2025-26 includes 8 anniversary nights + 20 additional promotional nights.
A15: 10 | B15: Fan Demand / Ticketing | C15: Giveaway items | D15: items | E15: =Assumptions!C34 | F15: =Assumptions!D34 | G15: =Assumptions!E34 | H15: =Assumptions!F34 | I15: =Assumptions!G34 | J15: =Assumptions!H34 | K15: Public input / projection | L15: Medium | M15: Official promo releases | N15: 2025-26 current public list includes five announced giveaways.
A16: 11 | B16: Fan Demand / Ticketing | C16: Pregame tailgates | D16: events | E16: =Assumptions!C35 | F16: =Assumptions!D35 | G16: =Assumptions!E35 | H16: =Assumptions!F35 | I16: =Assumptions!G35 | J16: =Assumptions!H35 | K16: Public input / projection | L16: Medium | M16: Official promo releases | N16: Counted / projected from public promo schedules.
A17: 12 | B17: Fan Demand / Ticketing | C17: STM entry price | D17: $ | E17: =Assumptions!C36 | F17: =Assumptions!D36 | G17: =Assumptions!E36 | H17: =Assumptions!F36 | I17: =Assumptions!G36 | J17: =Assumptions!H36 | K17: Public input / projection | L17: High | M17: Official ticketing releases | N17: Gulls Elite floor price.
A18: 13 | B18: Fan Demand / Ticketing | C18: STM entry price per game | D18: $ | E18: =IFERROR(E17/E7,0) | F18: =IFERROR(F17/F7,0) | G18: =IFERROR(G17/G7,0) | H18: =IFERROR(H17/H7,0) | I18: =IFERROR(I17/I7,0) | J18: =IFERROR(J17/J7,0) | K18: Derived | L18: High | M18: STM entry price ÷ home games | N18: Season-ticket floor divided by home games.
A19: 14 | B19: Fan Demand / Ticketing | C19: Single-game floor (box office / public) | D19: $ | E19: =Assumptions!C37 | F19: =Assumptions!D37 | G19: =Assumptions!E37 | H19: =Assumptions!F37 | I19: =Assumptions!G37 | J19: =Assumptions!H37 | K19: Public input / estimate / projection | L19: Medium | M19: Official ticketing releases | N19: 2024-25 floor is interpolated estimate.
A20: 15 | B20: Fan Demand / Ticketing | C20: Single-game floor (online incl. fees) | D20: $ | E20: =Assumptions!C38 | F20: =Assumptions!D38 | G20: =Assumptions!E38 | H20: =Assumptions!F38 | I20: =Assumptions!G38 | J20: =Assumptions!H38 | K20: Estimate / projection | L20: Medium | M20: Official 2025-26 ticketing release | N20: 2025-26 is official; 2024-25 and 2026-27 are modeled estimates.
A21: 16 | B21: Fan Demand / Ticketing | C21: College ticket price | D21: $ | E21: =Assumptions!C39 | F21: =Assumptions!D39 | G21: =Assumptions!E39 | H21: =Assumptions!F39 | I21: =Assumptions!G39 | J21: =Assumptions!H39 | K21: Public input / projection | L21: Medium | M21: Official college page | N21: Current season official price.
A22: 17 | B22: Fan Demand / Ticketing | C22: Family pack price floor | D22: $ | E22: =Assumptions!C40 | F22: =Assumptions!D40 | G22: =Assumptions!E40 | H22: =Assumptions!F40 | I22: =Assumptions!G40 | J22: =Assumptions!H40 | K22: Public input / projection | L22: Medium | M22: Official family-pack page | N22: Current-season official product.
A23: 18 | B23: Fan Demand / Ticketing | C23: Group minimum size | D23: tickets | E23: =Assumptions!C41 | F23: =Assumptions!D41 | G23: =Assumptions!E41 | H23: =Assumptions!F41 | I23: =Assumptions!G41 | J23: =Assumptions!H41 | K23: Public / context | L23: Medium | M23: Official group page | N23: Assumed stable historically.
A24: 19 | B24: Fan Demand / Ticketing | C24: Max mini-plan discount | D24: pct | E24: =Assumptions!C42 | F24: =Assumptions!D42 | G24: =Assumptions!E42 | H24: =Assumptions!F42 | I24: =Assumptions!G42 | J24: =Assumptions!H42 | K24: Estimate / projection | L24: Low | M24: Public current mini-plan page | N24: Historical values are conservative placeholders.
A25: 20 | B25: Fan Demand / Ticketing | C25: Weighted average ticket price (modeled) | D25: $ | E25: =Assumptions!C43 | F25: =Assumptions!D43 | G25: =Assumptions!E43 | H25: =Assumptions!F43 | I25: =Assumptions!G43 | J25: =Assumptions!H43 | K25: Estimate / projection | L25: Medium | M25: Model methodology | N25: Modeled from ticket product mix and public price anchors.
A26: 21 | B26: Fan Demand / Ticketing | C26: Group sales share of gate | D26: pct | E26: =Assumptions!C44 | F26: =Assumptions!D44 | G26: =Assumptions!E44 | H26: =Assumptions!F44 | I26: =Assumptions!G44 | J26: =Assumptions!H44 | K26: Estimate / projection | L26: Low | M26: Model methodology | N26: Logical range based on minor-league group channel importance.
A27: 22 | B27: Fan Demand / Ticketing | C27: Premium seating yield | D27: $ | E27: =Assumptions!C45 | F27: =Assumptions!D45 | G27: =Assumptions!E45 | H27: =Assumptions!F45 | I27: =Assumptions!G45 | J27: =Assumptions!H45 | K27: Estimate / projection | L27: Low | M27: Model methodology | N27: Embedded within gate yield; not additive in revenue total.
A28: 23 | B28: Fan Demand / Ticketing | C28: STM base (FSE) | D28: FSE | E28: =Assumptions!C46 | F28: =Assumptions!D46 | G28: =Assumptions!E46 | H28: =Assumptions!F46 | I28: =Assumptions!G46 | J28: =Assumptions!H46 | K28: Estimate / projection | L28: Low | M28: Model methodology | N28: Modeled from attendance and ticket mix.
A29: 24 | B29: Fan Demand / Ticketing | C29: STM retention rate | D29: pct | E29: =Assumptions!C47 | F29: =Assumptions!D47 | G29: =Assumptions!E47 | H29: =Assumptions!F47 | I29: =Assumptions!G47 | J29: =Assumptions!H47 | K29: Estimate / projection | L29: Low | M29: Model methodology | N29: Modeled range.
A30: 2. Revenue Engine & Economics
A31: 25 | B31: Revenue Engine | C31: Gate revenue | D31: $ | E31: =E8*E25 | F31: =F8*F25 | G31: =G8*G25 | H31: =H8*H25 | I31: =I8*I25 | J31: =J8*J25 | K31: Derived | L31: Medium | M31: Total attendance × WATP | N31: Modeled gate revenue using weighted average ticket price.
A32: 26 | B32: Revenue Engine | C32: Facility fee per paid ticket | D32: $ | E32: =Assumptions!C68 | F32: =Assumptions!D68 | G32: =Assumptions!E68 | H32: =Assumptions!F68 | I32: =Assumptions!G68 | J32: =Assumptions!H68 | K32: Estimate | L32: Low | M32: Lease-era reporting / model assumption | N32: Publicly discussed current surcharge structure; early years not confirmed.
A33: 27 | B33: Revenue Engine | C33: Facility fee liability | D33: $ | E33: =IFERROR(E8*E32,"") | F33: =IFERROR(F8*F32,"") | G33: =IFERROR(G8*G32,"") | H33: =IFERROR(H8*H32,"") | I33: =IFERROR(I8*I32,"") | J33: =IFERROR(J8*J32,"") | K33: Derived | L33: Low | M33: Total attendance × facility fee | N33: Pass-through city/venue fee liability estimate.
A34: 28 | B34: Revenue Engine | C34: Revenue per available seat (RevPAS) | D34: $ | E34: =IFERROR(E31/(E56*E7),"") | F34: =IFERROR(F31/(F56*F7),"") | G34: =IFERROR(G31/(G56*G7),"") | H34: =IFERROR(H31/(H56*H7),"") | I34: =IFERROR(I31/(I56*I7),"") | J34: =IFERROR(J31/(J56*J7),"") | K34: Derived | L34: Medium | M34: Gate ÷ (capacity × home games) | N34: Uses 12,920 hockey capacity.
A35: 29 | B35: Revenue Engine | C35: F&B per-cap gross | D35: $ | E35: =Assumptions!C48 | F35: =Assumptions!D48 | G35: =Assumptions!E48 | H35: =Assumptions!F48 | I35: =Assumptions!G48 | J35: =Assumptions!H48 | K35: Estimate / projection | L35: Low | M35: Model methodology | N35: Gross in-building spend, not team net.
A36: 30 | B36: Revenue Engine | C36: Team concession commission rate | D36: pct | E36: =Assumptions!C49 | F36: =Assumptions!D49 | G36: =Assumptions!E49 | H36: =Assumptions!F49 | I36: =Assumptions!G49 | J36: =Assumptions!H49 | K36: Estimate | L36: Low | M36: Model methodology | N36: Private split; modeled nominal rate.
A37: 31 | B37: Revenue Engine | C37: Concession commission revenue | D37: $ | E37: =E8*E35*E36 | F37: =F8*F35*F36 | G37: =G8*G35*G36 | H37: =H8*H35*H36 | I37: =I8*I35*I36 | J37: =J8*J35*J36 | K37: Derived | L37: Low | M37: Attendance × F&B per-cap × commission rate | N37: Team-side concession revenue estimate.
A38: 32 | B38: Revenue Engine | C38: Merchandise per-cap | D38: $ | E38: =Assumptions!C50 | F38: =Assumptions!D50 | G38: =Assumptions!E50 | H38: =Assumptions!F50 | I38: =Assumptions!G50 | J38: =Assumptions!H50 | K38: Estimate / projection | L38: Low | M38: Model methodology | N38: Modeled team-store spend per attendee.
A39: 33 | B39: Revenue Engine | C39: Merchandise revenue | D39: $ | E39: =E8*E38 | F39: =F8*F38 | G39: =G8*G38 | H39: =H8*H38 | I39: =I8*I38 | J39: =J8*J38 | K39: Derived | L39: Low | M39: Attendance × merch per-cap | N39: Modeled gross merchandise revenue.
A40: 34 | B40: Revenue Engine | C40: Parking fee assumption | D40: $ | E40: =Assumptions!C51 | F40: =Assumptions!D51 | G40: =Assumptions!E51 | H40: =Assumptions!F51 | I40: =Assumptions!G51 | J40: =Assumptions!H51 | K40: Estimate / projection | L40: Low | M40: Public parking page + model | N40: Event-specific public fee structure; year values are model anchors.
A41: 35 | B41: Revenue Engine | C41: Average auto occupancy | D41: persons | E41: =Assumptions!C52 | F41: =Assumptions!D52 | G41: =Assumptions!E52 | H41: =Assumptions!F52 | I41: =Assumptions!G52 | J41: =Assumptions!H52 | K41: Estimate | L41: Low | M41: Model methodology | N41: Transport assumption for parking yield.
...

Sheet Scenario_OnePager
A1: 2026-27 Scenario One-Page Assessment
A2: Interactive planning tab: selected scenario drives the full workbook; this page shows the levers that move revenue, EBITDA, valuation, and demand.
A3: Selected Revenue | D3: Selected EBITDA | G3: Selected Valuation | J3: Selected Attendance | M3: Scenario
A4: =IFERROR(Master_Model!$J$52,0) | D4: =IFERROR(Master_Model!$J$98,0) | G4: =IFERROR(Master_Model!$J$102,0) | J4: =IFERROR(Master_Model!$J$6,0) | M4: =Executive_Dashboard!$C$3
A10: Lever | B10: Baseline | C10: Tactical Upside | D10: Aggressive Growth | E10: Strategic Operational Impact
A11: Attendance Uplift | B11: +3% | C11: +6% | D11: +9% | E11: Leverage San Diego’s veteran and active-duty population with military nights, referral loops, and community endurance-style activations to lift mid-week volume.
A12: Ticket Yield / WATP | B12: +3.2% | C12: +5.0% | D12: +7.5% | E12: Tighten dynamic pricing around Friday/Saturday demand, anniversary games, and premium seat clusters while keeping entry products accessible.
A13: Sponsorship Yield | B13: +9.3% | C13: +12.0% | D13: +16.0% | E13: Bundle digital, theme-night, signage, and hospitality inventory into fewer, higher-value packages with clearer audience data.
A14: F&B Per-Cap | B14: +3.2% | C14: +5.0% | D14: +7.0% | E14: Use Stella Lounge, tailgate, and bundle mechanics to lift mix and spend instead of relying on raw attendance alone.
A15: Merch Conversion | B15: +4.4% | C15: +6.0% | D15: +8.0% | E15: Deploy event-night capsules, auctioned specialty product, and QR-based game-night offers to improve same-visit conversion.
A16: Digital Funnel | B16: +8.0% traffic | C16: +12.0% traffic | D16: +16.0% traffic | E16: Segment email/SMS, simplify mobile landing pages, and retarget first-time buyers into flex-plan, college, and group follow-up journeys.
H20: Team | I20: 2025-26 Attendance | J20: Ticket Entry Anchor | K20: Modeled WATP
H21: San Diego Gulls | I21: 7403 | J21: $23 box office / $28.75 online | K21: 25.4
H22: Coachella Valley Firebirds | I22: 9805 | J22: Premium-heavy desert market / individual-game on-sale | K22: 29.5
H23: Henderson Silver Knights | I23: 4856 | J23: Value nights + group savings up to 40% | K23: 23
H25: Benchmark note: non-Gulls WATP values are directional estimates using public ticket products, market positioning, and attendance context—not disclosed team financials.

Sheet Source_Log
A1: Metric | B1: Category | C1: 2021-22 | D1: 2022-23 | E1: 2023-24 | F1: 2024-25 | G1: 2025-26 | H1: 2026-27 | I1: Unit | J1: Source / Method | K1: Status
A2: 2026-27 attendance growth assumption | B2: CONTROL | H2: 0.03 | I2: pct | J2: Model control | K2: Control
A3: 2026-27 WATP growth assumption | B3: CONTROL | H3: 0.032 | I3: pct | J3: Model control | K3: Control
A4: 2026-27 sponsorship growth assumption | B4: CONTROL | H4: 0.093 | I4: pct | J4: Model control | K4: Control
A5: 2026-27 per-cap F&B growth assumption | B5: CONTROL | H5: 0.032 | I5: pct | J5: Model control | K5: Control
A6: 2026-27 merch per-cap growth assumption | B6: CONTROL | H6: 0.044 | I6: pct | J6: Model control | K6: Control
A7: 2026-27 STM price growth assumption | B7: CONTROL | H7: 0.03 | I7: pct | J7: Model control | K7: Control
A8: 2026-27 single-game price growth assumption | B8: CONTROL | H8: 0.043 | I8: pct | J8: Model control | K8: Control
A9: 2026-27 website traffic growth assumption | B9: CONTROL | H9: 0.08 | I9: pct | J9: Model control | K9: Control
A10: Average attendance | B10: ATTENDANCE | C10: 6992 | D10: 6953 | E10: 7249 | F10: 7262 | G10: 7403 | I10: fans/game | J10: https://www.hockeydb.com/stte/san-diego-gulls-11619.html | K10: Public/Projection
A11: Home games | B11: ATTENDANCE | C11: 34 | D11: 36 | E11: 36 | F11: 36 | G11: 36 | H11: 36 | I11: games | J11: https://www.sandiegogulls.com/news/detail/san-diego-gulls-2021-22-schedule-announced | K11: Public
A12: Hockey seating capacity | B12: VENUE | C12: 12920 | D12: 12920 | E12: 12920 | F12: 12920 | G12: 12920 | H12: 12920 | I12: seats | J12: https://www.sandiegogulls.com/assets/doc/2021-22-San-Diego-Gulls-Media-Guide-compressed-92470e4558.pdf | K12: Context
A13: General venue capacity | B13: VENUE | C13: 14000 | D13: 14000 | E13: 14000 | F13: 14000 | G13: 14000 | H13: 14000 | I13: seats | J13: https://pechangaarenasd.com/about/ | K13: Public
A14: Home weekend dates | B14: SCHEDULE | C14: 23 | D14: 23 | E14: 26 | F14: 25 | G14: 25 | H14: 25 | I14: dates | J14: Multiple official schedule releases on sandiegogulls.com | K14: Public
A15: Friday home games | B15: SCHEDULE | C15: 11 | D15: 12 | E15: 12 | F15: 9 | G15: 10 | H15: 10 | I15: games | J15: Multiple official schedule releases on sandiegogulls.com | K15: Public
A16: Saturday home games | B16: SCHEDULE | C16: 11 | D16: 11 | E16: 12 | F16: 14 | G16: 10 | H16: 11 | I16: games | J16: Multiple official schedule releases on sandiegogulls.com | K16: Public/Projection
A17: Sunday home games | B17: SCHEDULE | C17: 1 | D17: 1 | E17: 2 | F17: 2 | G17: 5 | H17: 4 | I17: games | J17: Multiple official schedule releases on sandiegogulls.com | K17: Public/Projection
A18: Back-to-back sets | B18: SCHEDULE | C18: 24 | D18: 21 | E18: 18 | F18: 20 | G18: 22 | H18: 22 | I18: sets | J18: Multiple official schedule releases on sandiegogulls.com | K18: Public
A19: Promotional/theme nights announced | B19: MARKETING | C19: 13 | D19: 15 | E19: 16 | F19: 23 | G19: 28 | H19: 30 | I19: nights | J19: Multiple official promo releases on sandiegogulls.com | K19: Public/Projection
A20: Giveaway items announced | B20: MARKETING | C20: 7 | D20: 6 | E20: 10 | F20: 11 | G20: 5 | H20: 6 | I20: items | J20: Multiple official promo releases on sandiegogulls.com | K20: Public/Projection
A21: Pregame tailgates | B21: MARKETING | C21: 6 | D21: 6 | E21: 7 | F21: 7 | G21: 7 | H21: 8 | I21: events | J21: Multiple official promo releases on sandiegogulls.com | K21: Public/Projection
A22: STM entry price | B22: TICKETING | C22: 476 | D22: 540 | E22: 540 | F22: 560 | G22: 614 | I22: $/seat | J22: Multiple official ticketing releases on sandiegogulls.com | K22: Public/Projection
A23: Single-game floor (box office / public) | B23: TICKETING | C23: 19 | D23: 21 | E23: 20 | F23: 22 | G23: 23 | I23: $/ticket | J23: Multiple official ticketing releases on sandiegogulls.com | K23: Public/Estimate/Projection
A24: Single-game floor (online incl. fees) | B24: TICKETING | F24: 27.5 | G24: 28.75 | H24: 29.75 | I24: $/ticket | J24: https://www.sandiegogulls.com/news/detail/single-game-tickets-available-now | K24: Estimate/Projection
A25: College ticket price | B25: TICKETING | G25: 17 | H25: 17.5 | I25: $/ticket | J25: https://www.sandiegogulls.com/tickets/college | K25: Public/Projection
A26: Family pack price floor | B26: TICKETING | G26: 130 | H26: 135 | I26: $/pack | J26: https://www.sandiegogulls.com/tickets/4-packs | K26: Public/Projection
A27: Group minimum size | B27: TICKETING | C27: 10 | D27: 10 | E27: 10 | F27: 10 | G27: 10 | H27: 10 | I27: tickets | J27: https://www.sandiegogulls.com/tickets/group-tickets | K27: Public/Context
A28: Max mini-plan discount | B28: TICKETING | C28: 0.15 | D28: 0.15 | E28: 0.2 | F28: 0.3 | G28: 0.3 | H28: 0.3 | I28: pct | J28: https://www.sandiegogulls.com/tickets/gulls-mini-plans | K28: Estimate/Projection
A29: Weighted average ticket price (modeled) | B29: TICKETING | C29: 22 | D29: 22.4 | E29: 23.4 | F29: 24.4 | G29: 25.4 | I29: $/ticket | J29: Model methodology | K29: Estimate/Projection
A30: Group sales share of gate | B30: TICKETING | C30: 0.16 | D30: 0.17 | E30: 0.18 | F30: 0.19 | G30: 0.2 | H30: 0.21 | I30: pct | J30: Model methodology | K30: Estimate/Projection
A31: Premium seating yield (included in gate) | B31: TICKETING | C31: 380000 | D31: 400000 | E31: 460000 | F31: 520000 | G31: 600000 | H31: 660000 | I31: $ | J31: Model methodology | K31: Estimate/Projection
A32: STM base (full-season equivalents) | B32: TICKETING | C32: 2300 | D32: 2350 | E32: 2450 | F32: 2550 | G32: 2700 | H32: 2780 | I32: FSE | J32: Model methodology | K32: Estimate/Projection
A33: STM retention rate | B33: TICKETING | C33: 0.77 | D33: 0.76 | E33: 0.78 | F33: 0.8 | G33: 0.82 | H33: 0.83 | I33: pct | J33: Model methodology | K33: Estimate/Projection
A34: F&B per-cap gross | B34: ANCILLARY | C34: 13 | D34: 13.4 | E34: 14 | F34: 14.8 | G34: 15.5 | I34: $/attendee | J34: Model methodology | K34: Estimate/Projection
A35: Team concession commission rate | B35: ANCILLARY | C35: 0.04 | D35: 0.04 | E35: 0.04 | F35: 0.04 | G35: 0.04 | H35: 0.04 | I35: pct | J35: Model methodology | K35: Estimate
A36: Merchandise per-cap | B36: ANCILLARY | C36: 3.6 | D36: 3.8 | E36: 4 | F36: 4.2 | G36: 4.5 | I36: $/attendee | J36: Model methodology | K36: Estimate/Projection
A37: Parking fee assumption | B37: ANCILLARY | C37: 15 | D37: 15 | E37: 15 | F37: 18 | G37: 20 | H37: 21 | I37: $/vehicle | J37: https://pechangaarenasd.com/plan-your-visit/directions-parking/ | K37: Estimate/Projection
A38: Average auto occupancy | B38: ANCILLARY | C38: 2.6 | D38: 2.6 | E38: 2.6 | F38: 2.5 | G38: 2.5 | H38: 2.5 | I38: persons/vehicle | J38: Model methodology | K38: Estimate
A39: Team share of parking | B39: ANCILLARY | C39: 0.05 | D39: 0.05 | E39: 0.05 | F39: 0.05 | G39: 0.05 | H39: 0.05 | I39: pct | J39: Model methodology | K39: Estimate
A40: Total sponsorship revenue | B40: SPONSORSHIP | C40: 1950000 | D40: 2000000 | E40: 2200000 | F40: 2450000 | G40: 2700000 | I40: $ | J40: Model methodology | K40: Estimate/Projection
...

Sheet Charts
A1: Dynamic Charts
A3: Metric | B3: 2021-22 | C3: 2022-23 | D3: 2023-24 | E3: 2024-25 | F3: 2025-26 | G3: 2026-27
A4: Average Attendance | B4: =IFERROR(Master_Model!E6,0) | C4: =IFERROR(Master_Model!F6,0) | D4: =IFERROR(Master_Model!G6,0) | E4: =IFERROR(Master_Model!H6,0) | F4: =IFERROR(Master_Model!I6,0) | G4: =IFERROR(Master_Model!J6,0)
A5: Gross Revenue | B5: =IFERROR(Master_Model!E52,0) | C5: =IFERROR(Master_Model!F52,0) | D5: =IFERROR(Master_Model!G52,0) | E5: =IFERROR(Master_Model!H52,0) | F5: =IFERROR(Master_Model!I52,0) | G5: =IFERROR(Master_Model!J52,0)
A6: EBITDA | B6: =IFERROR(Master_Model!E98,0) | C6: =IFERROR(Master_Model!F98,0) | D6: =IFERROR(Master_Model!G98,0) | E6: =IFERROR(Master_Model!H98,0) | F6: =IFERROR(Master_Model!I98,0) | G6: =IFERROR(Master_Model!J98,0)
A7: Implied Valuation | B7: =IFERROR(Master_Model!E102,0) | C7: =IFERROR(Master_Model!F102,0) | D7: =IFERROR(Master_Model!G102,0) | E7: =IFERROR(Master_Model!H102,0) | F7: =IFERROR(Master_Model!I102,0) | G7: =IFERROR(Master_Model!J102,0)

Sheet Export_PDF_Macro
A1: PDF Export Macro (ready-to-paste VBA)
A2: A live VBA module cannot be embedded from this environment, but the code below is ready to paste into Excel VBA and assign to a button.
A4: Sub ExportAssessmentPDF() Sheets(Array("Scenario_OnePager", "Charts")).Select ActiveSheet.ExportAsFixedFormat Type:=xlTypePDF, _ Filename:=ThisWorkbook.Path & "\\San_Diego_Gulls_Assessment.pdf", _ Quality:=xlQualityStandard, IncludeDocProperties:=True, _ IgnorePrintAreas:=False, OpenAfterPublish:=False Sheets("Executive_Dashboard").Select End Sub
